exports.registerUser = async (req, res) => {
  try {
    res.status(201).send({ message: "Test passed!" });
  } catch (err) {
    console.error("Test error:", err);
    res.status(500).send({ message: "Internal Server Error" });
  }
};

exports.loginUser = async (req, res) => {
  try {
    res.status(201).send({ message: "Test passed!" });
  } catch (err) {
    console.error("Test error:", err);
    res.status(500).send({ message: "Internal Server Error" });
  }
};

exports.forgotPassword = async (req, res) => {
  try {
    res.status(201).send({ message: "Test passed!" });
  } catch (err) {
    console.error("Test error:", err);
    res.status(500).send({ message: "Internal Server Error" });
  }
};

exports.resetPassword = async (req, res) => {
  try {
    res.status(201).send({ message: "Test passed!" });
  } catch (err) {
    console.error("Test error:", err);
    res.status(500).send({ message: "Internal Server Error" });
  }
};

exports.getUserInfo = async (req, res) => {
  try {
    res.status(201).send({ message: "Test passed!" });
  } catch (err) {
    console.error("Test error:", err);
    res.status(500).send({ message: "Internal Server Error" });
  }
};

exports.updateUser = async (req, res) => {
  try {
    res.status(201).send({ message: "Test passed!" });
  } catch (err) {
    console.error("Test error:", err);
    res.status(500).send({ message: "Internal Server Error" });
  }
};

exports.deleteUser = async (req, res) => {
  try {
    res.status(201).send({ message: "Test passed!" });
  } catch (err) {
    console.error("Test error:", err);
    res.status(500).send({ message: "Internal Server Error" });
  }
};

exports.getUserOrders = async (req, res) => {
  try {
    res.status(201).send({ message: "Test passed!" });
  } catch (err) {
    console.error("Test error:", err);
    res.status(500).send({ message: "Internal Server Error" });
  }
};
